<mujoco model="aliengo">
    <compiler angle="radian" meshdir="./assets/" autolimits="true"/>
    <option cone="elliptic" impratio="100" />
    <size njmax="500" nconmax="100" />
    <option gravity='0 0 -9.806' timestep='0.002'/>


    <default>

        <joint damping="0." armature="0.01" frictionloss="0." />
        
        
        <default class="leader/visual">
            <geom type="mesh" contype="0" conaffinity="0" group="2"/>
        </default>
        <default class="leader/visual_arm">
            <geom type="mesh" contype="0" conaffinity="0" group="2"/>
        </default>
        <default class="leader/collision">
            <geom group="3" rgba="0.2 0.2 0.2 0.5"/>
        </default> 

        <default class="leader/hip">
            <motor ctrlrange="-4400.4 4400.4"/>
        </default>
        <default class="leader/thigh">
            <motor ctrlrange="-3500.278 3500.278"/>
        </default>
        <default class="leader/calf">
            <motor ctrlrange="-3500.278 3500.278"/>
        </default>

    </default>

    <asset>
        <mesh name="leader/trunk" file="assets/trunk.stl" />
        <mesh name="leader/hip" file="assets/hip.stl" />
        <mesh name="leader/thigh_mirror" file="assets/thigh_mirror.stl" />
        <mesh name="leader/calf" file="assets/calf.stl" />
        <mesh name="leader/thigh" file="assets/thigh.stl" />
        <mesh name="leader/base_arm_link" file="assets/base_arm_link.stl" />
        <mesh name="leader/arm_link_1" file="assets/arm_link_1.stl" />
        <mesh name="leader/arm_link_2" file="assets/arm_link_2.stl" />
        <mesh name="leader/arm_link_3" file="assets/arm_link_3.stl" />
        
    </asset>

  <worldbody>
        <body name="leader/trunk" pos="0 0 0.4">
            <inertial pos="0.00846406 0.00404455 -0.000762916" quat="-3.12625e-05 0.708321 0.00247254 0.705886" mass="13.042" diaginertia="0.174706 0.161175 0.033357" />
            <freejoint/>
            
            <!-- trunk visual mesh and collision -->
            <geom type="mesh" class="leader/visual" rgba="0.2 0.2 0.2 1" mesh="leader/trunk" />
            <!-- <geom type="mesh" class="leader/visual" rgba="0.2 0.2 0.2 1" mesh="leader/trunk" mass="13.042"/> -->
            <geom type="box" class="leader/collision" size="0.18 0.075 0.056"/>

            <!-- modify this to add payload -->
            <!--body name="payload" pos="0 0 0">
                <geom type="box" mass="0.01" pos="0 0 0.1" size="0.05 0.05 0.05" rgba="1 0 0 0.3"/>
            </body-->
           
            <!-- imu and camera -->
            <site name="imu" pos="0 0 0"/>
            <camera name="leader/robotcam" pos="0.31 -0.005 0.00292751" quat= "0.4 0.4 -0.4 -0.4"/> 
            <camera name="top" pos="0 0 2" quat= "0.4 0.4 -0.4 -0.4"/> 

            <!-- FL leg -->
            <body name="leader/FL_hip" pos="0.2399 0.051 0">
                <inertial pos="-0.022191 0.015144 -1.5e-05" quat="-0.0135493 0.706835 0.0117635 0.707151" mass="1.993" diaginertia="0.00558695 0.00491009 0.00290132" />
                <joint name="leader/FL_hip_joint" pos="0 0 0" axis="1 0 0" limited="true" range="-1.22173 1.22173" />
                
                <!-- FL_hip visual mesh and collision -->
                <geom type="mesh" class="leader/visual" rgba="0.2 0.2 0.2 1" mesh="leader/hip"/>
                
                <!-- <geom type="mesh" class="leader/visual" rgba="0.2 0.2 0.2 1" mesh="leader/hip" mass="1.993"/>  -->

                <geom type="capsule" class="leader/collision" size="0.046 0.0209" pos="0 0.083 0" quat="0.707107 0.707107 0 0"/>
                
                <body name="leader/FL_thigh" pos="0 0.083 0">
                    <inertial pos="-0.005607 -0.003877 -0.048199" quat="0.717987 -0.031246 -0.0335669 0.694544" mass="0.639" diaginertia="0.0058474 0.00571186 0.000324584" />
                    <joint name="leader/FL_thigh_joint" pos="0 0 0" axis="0 1 0" />
                    
                    <!-- FL_thigh visual mesh and collision -->
                    <geom type="mesh" class="leader/visual" rgba="0.2 0.2 0.2 1" mesh="leader/thigh"/>
                    <!-- <geom type="mesh" class="leader/visual" rgba="0.2 0.2 0.2 1" mesh="leader/thigh" mass="0.639" /> -->
                    <geom type="box" class="leader/collision" size="0.125 0.0187 0.0215" pos="0 0 -0.125" quat="0.707107 0 0.707107 0"/>
                    
                    <body name="leader/FL_calf" pos="0 0 -0.25">
                        <inertial pos="0.00215606 4.88427e-05 -0.166671" quat="0.707462 0.00517582 0.00535172 0.706712" mass="0.267" diaginertia="0.00690975 0.00689712 5.4885e-05" />

                        <joint name="leader/FL_calf_joint" pos="0 0 0" axis="0 1 0" limited="true" range="-2.77507 -0.645772" />
                        
                        <!-- FL_calf visual mesh and collision -->
                        <geom type="mesh" class="leader/visual" rgba="0 0 0 1" mesh="leader/calf" />
                        <!-- <geom type="mesh" class="leader/visual" rgba="0 0 0 1" mesh="leader/calf" mass="0.267"/> -->
                        <geom type="box" class="leader/collision" size="0.125 0.0104 0.008" pos="0 0 -0.125" quat="0.707107 0 0.707107 0"/>
                        
                        <!-- FL_foot only collision -->
                        <geom name="FL1" class="leader/collision" size="0.0265" pos="0 0 -0.25" />
                    </body>
                </body>
            </body>

            <!-- FR leg -->
            <body name="leader/FR_hip" pos="0.2399 -0.051 0">
                <inertial pos="-0.022191 -0.015144 -1.5e-05" quat="0.0135493 0.706835 -0.0117635 0.707151" mass="1.993" diaginertia="0.00558695 0.00491009 0.00290132" />
                <joint name="leader/FR_hip_joint" pos="0 0 0" axis="1 0 0" limited="true" range="-1.22173 1.22173" />
                
                <!-- FR_hip visual mesh and collision -->
                <geom type="mesh" mesh="leader/hip" class="leader/visual" quat="0 1 0 0" rgba="0.2 0.2 0.2 1"/>
                <geom type="capsule" class="leader/collision" size="0.046 0.0209" pos="0 -0.083 0" quat="0.707107 0.707107 0 0"/>
                
                <body name="leader/FR_thigh" pos="0 -0.083 0">
                    <inertial pos="-0.005607 0.003877 -0.048199" quat="0.694544 -0.0335669 -0.031246 0.717987" mass="0.639" diaginertia="0.0058474 0.00571186 0.000324584" />
                    <joint name="leader/FR_thigh_joint" pos="0 0 0" axis="0 1 0" />
                    
                    <!-- FR_thigh visual mesh and collision -->
                    <geom type="mesh" mesh="leader/thigh_mirror" class="leader/visual" rgba="0.2 0.2 0.2 1" />
                    <geom type="box" class="leader/collision" size="0.125 0.0187 0.0215" pos="0 0 -0.125" quat="0.707107 0 0.707107 0"/>
                    
                    <body name="leader/FR_calf" pos="0 0 -0.25">
                        <inertial pos="0.00215606 4.88427e-05 -0.166671" quat="0.707462 0.00517582 0.00535172 0.706712" mass="0.267" diaginertia="0.00690975 0.00689712 5.4885e-05" />
                        <joint name="leader/FR_calf_joint" pos="0 0 0" axis="0 1 0" limited="true" range="-2.77507 -0.645772" />
                        
                        <!-- FR_calf visual mesh and collision -->
                        <geom type="mesh" mesh="leader/calf" class="leader/visual" rgba="0 0 0 1"/>
                        <geom type="box" class="leader/collision" size="0.125 0.0104 0.008" pos="0 0 -0.125" quat="0.707107 0 0.707107 0"/>
                        
                        <!-- FR_foot only collision -->
                        <geom name="FR1" class="leader/collision" size="0.0265" pos="0 0 -0.25"/>
                    </body>
                </body>
            </body>
            
            <!-- RL leg -->
            <body name="leader/RL_hip" pos="-0.2399 0.051 0">
                <inertial pos="0.022191 0.015144 -1.5e-05" quat="0.0117635 0.707151 -0.0135493 0.706835" mass="1.993" diaginertia="0.00558695 0.00491009 0.00290132" />
                <joint name="leader/RL_hip_joint" pos="0 0 0" axis="1 0 0" limited="true" range="-1.22173 1.22173" />
                
                <!-- RL_hip visual mesh and collision -->
                <geom type="mesh" class="leader/visual" quat="0 0 1 0" rgba="0.2 0.2 0.2 1" mesh="leader/hip"/>
                <geom type="capsule" class="leader/collision" size="0.046 0.0209" pos="0 0.083 0" quat="0.707107 0.707107 0 0"/>
                
                <body name="leader/RL_thigh" pos="0 0.083 0">
                    <inertial pos="-0.005607 -0.003877 -0.048199" quat="0.717987 -0.031246 -0.0335669 0.694544" mass="0.639" diaginertia="0.0058474 0.00571186 0.000324584" />
                    <joint name="leader/RL_thigh_joint" pos="0 0 0" axis="0 1 0" />
                    
                    <!-- RL_thigh visual mesh and collision -->
                    <geom type="mesh" class="leader/visual" rgba="0.2 0.2 0.2 1" mesh="leader/thigh"/>
                    <geom type="box" class="leader/collision" size="0.125 0.0187 0.0215" pos="0 0 -0.125" quat="0.707107 0 0.707107 0"/>
                    
                    <body name="leader/RL_calf" pos="0 0 -0.25">
                        <inertial pos="0.00215606 4.88427e-05 -0.166671" quat="0.707462 0.00517582 0.00535172 0.706712" mass="0.267" diaginertia="0.00690975 0.00689712 5.4885e-05" />
                        <joint name="leader/RL_calf_joint" pos="0 0 0" axis="0 1 0" limited="true" range="-2.77507 -0.645772" />
                        
                        <!-- RL_calf visual mesh and collision -->
                        <geom type="mesh" class="leader/visual" rgba="0 0 0 1" mesh="leader/calf"/>
                        <geom type="box" class="leader/collision" size="0.125 0.0104 0.008" pos="0 0 -0.125" quat="0.707107 0 0.707107 0"/>
                        
                        <!-- RL_foot only collision -->
                        <geom name="RL1" class="leader/collision" size="0.0265" pos="0 0 -0.25"/>
                    </body>
                </body>
            </body>
            
            <!-- RR leg -->
            <body name="leader/RR_hip" pos="-0.2399 -0.051 0">
                <inertial pos="0.022191 -0.015144 -1.5e-05" quat="-0.0117635 0.707151 0.0135493 0.706835" mass="1.993" diaginertia="0.00558695 0.00491009 0.00290132" />
                <joint name="leader/RR_hip_joint" pos="0 0 0" axis="1 0 0" limited="true" range="-1.22173 1.22173" />
                
                <!-- RR_hip visual mesh and collision -->
                <geom type="mesh" class="leader/visual" quat="0 0 0 -1" rgba="0.2 0.2 0.2 1" mesh="leader/hip"/>
                <geom type="capsule" class="leader/collision" size="0.046 0.0209" pos="0 -0.083 0" quat="0.707107 0.707107 0 0"/>
                
                <body name="leader/RR_thigh" pos="0 -0.083 0">
                    <inertial pos="-0.005607 0.003877 -0.048199" quat="0.694544 -0.0335669 -0.031246 0.717987" mass="0.639" diaginertia="0.0058474 0.00571186 0.000324584" />
                    <joint name="leader/RR_thigh_joint" pos="0 0 0" axis="0 1 0" />
                    
                    <!-- RR_thigh visual mesh and collision -->
                    <geom type="mesh" class="leader/visual" rgba="0.2 0.2 0.2 1" mesh="leader/thigh_mirror"/>
                    <geom type="box" class="leader/collision" size="0.125 0.0187 0.0215" pos="0 0 -0.125" quat="0.707107 0 0.707107 0"/>
                    
                    <body name="leader/RR_calf" pos="0 0 -0.25">
                        <inertial pos="0.00215606 4.88427e-05 -0.166671" quat="0.707462 0.00517582 0.00535172 0.706712" mass="0.267" diaginertia="0.00690975 0.00689712 5.4885e-05" />
                        <joint name="leader/RR_calf_joint" pos="0 0 0" axis="0 1 0" limited="true" range="-2.77507 -0.645772" />
                        
                        <!-- RR_calf visual mesh and collision -->
                        <geom type="mesh" class="leader/visual" rgba="0 0 0 1" mesh="leader/calf"/>
                        <geom type="box" class="leader/collision" size="0.125 0.0104 0.008" pos="0 0 -0.125" quat="0.707107 0 0.707107 0"/>
                        
                        <!-- RR_foot only collision -->
                        <geom name="RR1" class="leader/collision" size="0.0265" pos="0 0 -0.25"/>
                    </body>
                </body>
            </body>
    <geom pos="-0.25 0 0.056" quat="-3.673205103346574e-06 -0.0 0.0 0.9999999999932537" type="mesh" class="leader/visual_arm"   contype="0" conaffinity="0"  rgba="0 0 0 1" mesh="leader/base_arm_link" />
    <body name="leader/pa_link_0_ext" pos="-0.25 0 0.13" quat="-3.673205103346574e-06 -0.0 0.0 0.9999999999932537" >
      <inertial pos="0.0248 0.0 0.0169" quat="1.0 0.0 0.0 0.0" mass="0.2" diaginertia="0.001586944 0.001907517 0.001903894" />

      <joint name="leader/arm_link_1_joint" pos="0. 0 0." axis="0 0 1" limited="true" range="-1.5 1.5"  stiffness="0.5" damping="0.5"/>
      <!-- Visual Mesh -->
      <geom quat="1 0 0 0" type="mesh"   class="leader/visual_arm"  contype="0" conaffinity="0"  rgba="0 0 0 1" mesh="leader/arm_link_1" />
      <geom type="box" class="leader/collision" size="0.05 0.05 0.04" pos="0. 0 -0.035"   quat="1.0 0.0 0.0 0.0"/>
      <body name="leader/pa_link_1_ext" pos="0.0498 0 0.034">
            <!-- <inertial pos="0.0909 0 0.0923" quat="0.707051 0.0451246 -0.0453544 0.704263" mass="0.554" diaginertia="0.00488868 0.00457 0.00135132"/> -->
            <inertial pos="0.08 0.0 0.12" quat ="0.9238983141513943 0.0 0.3826380863272911 0.0" mass="0.2" diaginertia="0.00457 0.003831 0.001409" />
            <joint name="leader/arm_link_2_joint" pos="0.01 0 0.0" axis="0 1 0" limited="false" range="0 1" stiffness="0.5" damping="0.5"/>
            
            <!-- Visual Mesh -->
            <geom quat="1 0 0 0" type="mesh" class="leader/visual_arm"  contype="0" conaffinity="0"  rgba="0 0 0 1" mesh="leader/arm_link_2" />
            <geom type="box" class="leader/collision" size="0.15 0.04 0.04" pos="0.08 0.0 0.125" quat ="0.5 0 -0.15 0.0"/>
            <!-- <geom size="0.15 0.04 0.03" pos="0.1 0 0.14" quat="0.939525 0 -0.342481 0" type="box" rgba="0.75294 0.75294 0.75294 1"/> -->
            <body name="leader/pa_link_2_ext" pos="0.1817 0 0.1845" quat="1 0 0 0">
              <!-- <inertial pos="0.0194003 0 -0.125002" quat="0.7 0.616 0.0 0.0" mass="0.25" diaginertia="0.0035088 0.001072 0.00351255"/> -->
              <inertial pos="0.0194 0.0 -0.125" quat="0.7160633926253526 0.6980352553717256 0.0 0.0" mass="0.1" diaginertia="0.00205088 0.0008072 0.00201255" />
              <!-- <inertial pos="0.0 0.0 -0.15" quat="1 0 0 0" mass="0.258" diaginertia="0.0018474 0.00171186 0.000324584" /> -->
              <!-- Visual Mesh -->
              <joint name="leader/arm_link_3_joint" pos="0. 0 0" axis="0 1 0" limited="false" range="-2 0.5" stiffness="0.5" damping="0.5"/>
              <!--  -->
              <!-- <geom size="0.0175 0.04 0.125" pos="0.0194 0 -0.125" type="box" rgba="0.75294 0.75294 0.75294 1"/> -->
              <geom quat="1 0 0 0" type="mesh" class="leader/visual_arm"  contype="0" conaffinity="0"  rgba="0 0 0 1" mesh="leader/arm_link_3" />
              <geom size="0.001" pos="0.0388 0 -0.25" rgba="0 0 0 1"/>
              <geom type="box" class="leader/collision" size="0.15 0.02 0.05" pos="0.02 0 -0.15" quat="0.707107 0 0.707107 0"/>
              <site name="eef" pos="0.04 0 -0.24" size="0.01" quat="1 0 0 0" rgba="0 0 0 0."/>
              <!-- This body is need for havign the right applied force -->
              <!-- <body name="follower/eef" pos="0.04 0 -0.25" quat="1 0 0 0">
              <inertial pos="0.0 0.0 0.0" quat="0.7160633926253526 0.6980352553717256 0.0 0.0" mass="0.05" diaginertia="0.00205088 0.0008072 0.00201255" />
                  <geom name="follower/eef" type="sphere" size="0.03" rgba="0.12156863 0.46666667 0.70588235 1.0" group="2"/>
              </body> -->

            </body>
        </body>
      </body>
    </body>
  </worldbody>



</mujoco>
